<?xml version="1.0"?>
<robot xmlns:xacro="http://www.ros.org/wiki/xacro">

    <joint name="base_arm_joint" type="continuous">
        <parent link="original"/>
        <child link="base_arm"/>
        <origin xyz="0 0 0.575"/>
        <axis xyz="0 0 1"/>
        <dynamics damping="1" friction="2" />
    </joint>

    <link name="base_arm">
        <visual>
            <origin xyz="0 0 0" rpy="0 0 0"/>
            <geometry>
                <cylinder length="0.04" radius="0.25" />
            </geometry>
            <material name="blue"/>
        </visual>
        <collision>
            <origin xyz="0 0 0" rpy="0 0 0"/>
            <geometry>
                <cylinder length="0.04" radius="0.05" />
            </geometry>
        </collision>
        <xacro:inertial_cylinder mass="0.1" length="0.04" radius="0.25">
            <origin xyz="0 0 0" rpy="0 0 0"/>
        </xacro:inertial_cylinder>
    </link>
    
    <gazebo reference="base_arm">
        <material>Gazebo/Blue</material>
        <mu1>1</mu1>
        <mu2>1</mu2>
    </gazebo>

    <joint name="base_arm_head_joint" type="fixed">
        <parent link="base_arm"/>
        <child link="base_arm_head"/>
        <origin xyz="0 0 0"/>
    </joint>

    <link name="base_arm_head">
        <visual>
            <origin xyz="0 0 0" rpy="0 0 0"/>
            <geometry>
                <box size="0.05 0.05 0.15"/>
            </geometry>
            <material name="blue"/>
        </visual>
        <collision>
            <origin xyz="0 0 0" rpy="0 0 0"/>
            <geometry>
                <box size="0.05 0.05 0.15"/>
            </geometry>
        </collision>
        <xacro:inertial_box mass="0.1" x="0.05" y="0.05" z="0.15">
            <origin xyz="0 0 0" rpy="0 0 0"/>
        </xacro:inertial_box>
    </link>
    
    <gazebo reference="base_arm_head">
        <material>Gazebo/Blue</material>
        <mu1>1</mu1>
        <mu2>1</mu2>
    </gazebo>

    <joint name="ton_arm_joint" type="revolute">
        <parent link="base_arm_head"/>
        <child link="ton_arm"/>
        <origin xyz="0 -0.06 0.05"/>
        <axis xyz="0 1 0"/>
        <limit lower="-1.57" upper="1.57" effort="10" velocity="1"/>
        <dynamics damping="1" friction="2" />
    </joint>

    <link name="ton_arm">
        <visual>
            <origin xyz="0 0 0.725" rpy="0 0 0"/>
            <geometry>
                <box size="0.05 0.07 1.5"/>
            </geometry>
            <material name="blue"/>
        </visual>
        <collision>
            <origin xyz="0 0 0.725" rpy="0 0 0"/>
            <geometry>
                <box size="0.05 0.07 1.5"/>
            </geometry>
        </collision>
        <xacro:inertial_box mass="0.1" x="0.05" y="0.07" z="1.5">
            <origin xyz="0 0 0.725" rpy="0 0 0"/>
        </xacro:inertial_box>
    </link>
    
    <gazebo reference="ton_arm">
        <material>Gazebo/Blue</material>
        <mu1>1</mu1>
        <mu2>1</mu2>
    </gazebo>

    <joint name="last_arm_joint" type="revolute">
        <parent link="ton_arm"/>
        <child link="last_arm"/>
        <origin xyz="0 0.07 1.45"/>
        <axis xyz="0 1 0"/>
        <limit lower="-3.14" upper="3.14" effort="10" velocity="1"/>
        <dynamics damping="1" friction="2" />
    </joint>

    <link name="last_arm">
        <visual>
            <origin xyz="0 0 0.65" rpy="0 0 0"/>
            <geometry>
                <box size="0.05 0.07 1.4"/>
            </geometry>
            <material name="blue"/>
        </visual>
        <collision>
            <origin xyz="0 0 0.65" rpy="0 0 0"/>
            <geometry>
                <box size="0.05 0.07 1.4"/>
            </geometry>
        </collision>
        <xacro:inertial_box mass="0.1" x="0.05" y="0.07" z="1.4">
            <origin xyz="0 0 0.65" rpy="0 0 0"/>
        </xacro:inertial_box>
    </link>
    
    <gazebo reference="last_arm">
        <material>Gazebo/Blue</material>
        <mu1>1</mu1>
        <mu2>1</mu2>
    </gazebo>

    <joint name="hand_joint" type="revolute">
        <parent link="last_arm"/>
        <child link="hand_arm"/>
        <origin xyz="0 0 1.375"/>
        <axis xyz="0 1 0"/>
        <limit lower="-3.14" upper="3.14" effort="10" velocity="1"/>
        <dynamics damping="1" friction="2" />
    </joint>

    <link name="hand_arm">
        <visual>
            <origin xyz="0 0 0" rpy="0 0 0"/>
            <geometry>
                <box size="0.05 0.05 0.05"/>
            </geometry>
            <material name="black"/>
        </visual>
        <collision>
            <origin xyz="0 0 0" rpy="0 0 0"/>
            <geometry>
                <box size="0.05 0.05 0.05"/>
            </geometry>
        </collision>
        <xacro:inertial_box mass="0.1" x="0.05" y="0.05" z="0.05">
            <origin xyz="0 0 0" rpy="0 0 0"/>
        </xacro:inertial_box>
    </link>
    
    <gazebo reference="hand_arm">
        <material>Gazebo/Black</material>
        <mu1>1</mu1>
        <mu2>1</mu2>
    </gazebo>

    <joint name="hand1_joint" type="fixed">
        <parent link="hand_arm"/>
        <child link="hand1_arm"/>
        <origin xyz="0 0 0.04"/>
    </joint>

    <link name="hand1_arm">
        <visual>
            <origin xyz="0 0 0" rpy="0 0 0"/>
            <geometry>
                <box size="0.04 0.6 0.01"/>
            </geometry>
            <material name="red"/>
        </visual>
        <collision>
            <origin xyz="0 0 0" rpy="0 0 0"/>
            <geometry>
                <box size="0.04 0.6 0.01"/>
            </geometry>
        </collision>
        <xacro:inertial_box mass="0.1" x="1" y="1" z="0.25">
            <origin xyz="0 0 0.4" rpy="0 0 0"/>
        </xacro:inertial_box>
    </link>
    
    <gazebo reference="hand1_arm">
        <material>Gazebo/Red</material>
        <mu1>1</mu1>
        <mu2>1</mu2>
    </gazebo>

    <!-- ส่วนอื่นๆของโมเดล URDF -->
    <joint name="finger_joint" type="prismatic">
        <parent link="hand1_arm"/>
        <child link="finger"/>
        <origin xyz="0 0 0" rpy="0 0 0"/>
        <axis xyz="0 1 0"/>
        <limit lower="0.02" upper="0.3" effort="100" velocity="0.1"/>
        <dynamics damping="1" friction="2" />
    </joint>

    <link name="finger">
        <visual>
            <origin xyz="0 0 0.3" rpy="0 0 0"/>
            <geometry>
                <box size="0.04 0.04 0.6"/>
            </geometry>
            <material name="blue"/>
        </visual>
        <collision>
            <origin xyz="0 0 0.3" rpy="0 0 0"/>
            <geometry>
                <box size="0.04 0.04 0.8"/>
            </geometry>
        </collision>
        <xacro:inertial_box mass="0.1" x="0.04" y="0.04" z="0.2">
            <origin xyz="0 0 0.1" rpy="0 0 0"/>
        </xacro:inertial_box>
    </link>

    <joint name="finger1_joint" type="prismatic">
        <parent link="hand1_arm"/>
        <child link="finger1"/>
        <origin xyz="0 0 0" rpy="0 0 0"/>
        <axis xyz="0 1 0"/>
        <limit lower="-0.02" upper="-0.3" effort="100" velocity="0.1"/>
        <dynamics damping="1" friction="2" />
    </joint>

    <link name="finger1">
        <visual>
            <origin xyz="0 0 0.3" rpy="0 0 0"/>
            <geometry>
                <box size="0.04 0.04 0.6"/>
            </geometry>
            <material name="blue"/>
        </visual>
        <collision>
            <origin xyz="0 0 0.3" rpy="0 0 0"/>
            <geometry>
                <box size="0.04 0.04 0.8"/>
            </geometry>
        </collision>
        <xacro:inertial_box mass="0.1" x="0.04" y="0.04" z="0.2">
            <origin xyz="0 0 0.1" rpy="0 0 0"/>
        </xacro:inertial_box>
    </link>
    
    <gazebo reference="finger">
        <material>Gazebo/Blue</material>
        <mu1>1</mu1>
        <mu2>1</mu2>
    </gazebo>

    <gazebo reference="finger1">
        <material>Gazebo/Blue</material>
        <mu1>1</mu1>
        <mu2>1</mu2>
    </gazebo>

</robot>