<?xml version="1.0"?>
<robot xmlns:xacro="http://www.ros.org/wiki/xacro">
    
    <!--tow-->
    <joint name="tow1_joint" type="revolute">
        <parent link="tow"/>
        <child link="tow1"/>
        <origin xyz="0 0.05 0" rpy="0 0 ${pi}"/>
        <axis xyz="0 0 1"/>
        <limit lower="-0.73" upper="0.73" effort="10" velocity="1"/>
    </joint>

    <link name="tow1">
        <visual>
            <origin xyz="0 0 0" rpy="0 0 0"/>
            <geometry>
                <mesh filename="file:///home/jirapat/models/tow.dae" scale="1 1 1"/>
            </geometry>
            <material name="red"/>
        </visual>
        <collision>
            <origin xyz="0 0 0" rpy="0 0 0"/>
            <geometry>
                <mesh filename="file:///home/jirapat/models/tow.dae" scale="1 1 1"/>
            </geometry>
        </collision>
        <xacro:inertial_box mass="0.01" x="0.5" y="0.5" z="0.05">
            <origin xyz="0 0 0" rpy="0 0 0"/>
        </xacro:inertial_box>
    </link>
    
    <gazebo reference="tow1">
        <material>Gazebo/Red</material>
        <mu1>1</mu1>
        <mu2>1</mu2>
    </gazebo>

    <!--cart-->
    <joint name="cart_joint" type="fixed">
        <parent link="tow1"/>
        <child link="cart"/>
        <origin xyz="0 -0.85 -0.1475" rpy="0 0 ${pi/2}"/>
    </joint>

    <link name="cart">
        <visual>
            <origin xyz="0 0 0" rpy="0 0 0"/>
            <geometry>
                <mesh filename="file:///home/jirapat/models/cart.dae" scale="1 1 1"/>
            </geometry>
            <material name="orange"/>
        </visual>
        <collision>
            <origin xyz="0 0 0" rpy="0 0 0"/>
            <geometry>
                <mesh filename="file:///home/jirapat/models/cart.dae" scale="1 1 1"/>
            </geometry>
        </collision>
        <xacro:inertial_box mass="0.5" x="1" y="1" z="0.2">
            <origin xyz="0 0 0.35" rpy="0 0 0"/>
        </xacro:inertial_box>
    </link>
    
    <gazebo reference="cart">
        <material>Gazebo/Orange</material>
        <mu1>1</mu1>
        <mu2>1</mu2>
    </gazebo>

    <!--cart_wheel-->
    <joint name="WheelFront21_joint" type="continuous">
        <parent link="cart"/>
        <child link="WheelFront21"/>
        <origin xyz="0.5 -0.65 0.03"/>
        <axis xyz="0 1 0"/>
    </joint>

    <link name="WheelFront21">
        <visual>
            <origin xyz="0 0 -0.175" rpy="0 0 0"/>
            <geometry>
                <mesh filename="file:///home/jirapat/models/WheelFront.dae" scale="1 1 1"/>
            </geometry>
            <material name="blue"/>
        </visual>
        <collision>
            <origin xyz="0 0 -0.175" rpy="0 0 0"/>
            <geometry>
                <mesh filename="file:///home/jirapat/models/WheelFront.dae" scale="1 1 1"/>
            </geometry>
        </collision>
        <xacro:inertial_cylinder mass="0.1" length="0.1" radius="0.07">
            <origin xyz="0 0 0" rpy="0 0 0"/>
        </xacro:inertial_cylinder>
    </link>
    
    <gazebo reference="WheelFront21">
        <material>Gazebo/Blue</material>
        <mu1>1</mu1>
        <mu2>1</mu2>
    </gazebo>

    <joint name="WheelFront22_joint" type="continuous">
        <parent link="cart"/>
        <child link="WheelFront22"/>
        <origin xyz="-0.5 -0.65 0.03"/>
        <axis xyz="0 1 0"/>
    </joint>

    <link name="WheelFront22">
        <visual>
            <origin xyz="0 0 -0.175" rpy="0 0 0"/>
            <geometry>
                <mesh filename="file:///home/jirapat/models/WheelFront.dae" scale="1 1 1"/>
            </geometry>
            <material name="blue"/>
        </visual>
        <collision>
            <origin xyz="0 0 -0.175" rpy="0 0 0"/>
            <geometry>
                <mesh filename="file:///home/jirapat/models/WheelFront.dae" scale="1 1 1"/>
            </geometry>
        </collision>
        <xacro:inertial_cylinder mass="0.1" length="0.1" radius="0.07">
            <origin xyz="0 0 0" rpy="0 0 0"/>
        </xacro:inertial_cylinder>
    </link>
    
    <gazebo reference="WheelFront22">
        <material>Gazebo/Blue</material>
        <mu1>1</mu1>
        <mu2>1</mu2>
    </gazebo>

     <joint name="WheelbackFront21_joint" type="continuous">
        <parent link="cart"/>
        <child link="WheelbackFront21"/>
        <origin xyz="0.5 0.65 0.03"/>
        <axis xyz="0 1 0"/>
    </joint>

    <link name="WheelbackFront21">
        <visual>
            <origin xyz="0 0 -0.175" rpy="0 0 0"/>
            <geometry>
                <mesh filename="file:///home/jirapat/models/WheelbackFront.dae" scale="1 1 1"/>
            </geometry>
            <material name="blue"/>
        </visual>
        <collision>
            <origin xyz="0 0 -0.175" rpy="0 0 0"/>
            <geometry>
                <mesh filename="file:///home/jirapat/models/WheelbackFront.dae" scale="1 1 1"/>
            </geometry>
        </collision>
        <xacro:inertial_cylinder mass="0.1" length="0.1" radius="0.07">
            <origin xyz="0 0 0" rpy="0 0 0"/>
        </xacro:inertial_cylinder>
    </link>
    
    <gazebo reference="WheelbackFront21">
        <material>Gazebo/Blue</material>
        <mu1>1</mu1>
        <mu2>1</mu2>
    </gazebo>

    <joint name="WheelbackFront22_joint" type="continuous">
        <parent link="cart"/>
        <child link="WheelbackFront22"/>
        <origin xyz="-0.5 0.65 0.03"/>
        <axis xyz="0 1 0"/>
    </joint>

    <link name="WheelbackFront22">
        <visual>
            <origin xyz="0 0 -0.175" rpy="0 0 0"/>
            <geometry>
                <mesh filename="file:///home/jirapat/models/WheelbackFront.dae" scale="1 1 1"/>
            </geometry>
            <material name="blue"/>
        </visual>
        <collision>
            <origin xyz="0 0 -0.175" rpy="0 0 0"/>
            <geometry>
                <mesh filename="file:///home/jirapat/models/WheelbackFront.dae" scale="1 1 1"/>
            </geometry>
        </collision>
        <xacro:inertial_cylinder mass="0.1" length="0.1" radius="0.07">
            <origin xyz="0 0 0" rpy="0 0 0"/>
        </xacro:inertial_cylinder>
    </link>
    
    <gazebo reference="WheelbackFront22">
        <material>Gazebo/Blue</material>
        <mu1>1</mu1>
        <mu2>1</mu2>
    </gazebo>

</robot>