<?xml version="1.0"?>
<robot xmlns:xacro="http://www.ros.org/wiki/xacro" >

    <xacro:include filename="inertial_macros.xacro" />

    <material name="white">
        <color rgba="1 1 1 1" />
    </material>

    <material name="orange">
        <color rgba="1 0.3 0.1 1"/>
    </material>

    <material name="blue">
        <color rgba="0.2 0.2 1 1"/>
    </material>

    <material name="black">
        <color rgba="0 0 0 1"/>
    </material>

    <material name="red">
        <color rgba="1 0 0 1"/>
    </material>

    <!-- BASE LINK -->

    <link name="original">

    </link>

    <joint name="base_joint" type="fixed">
        <parent link="original"/>
        <child link="base"/>
        <origin xyz="0 0 0"/>
    </joint>

    <link name="base">
        <visual>
            <origin xyz="0 0 0.1525" rpy="0 0 0"/>
            <geometry>
                <mesh filename="file:///home/jirapat/models/base.dae" scale="1 1 1"/>
            </geometry>
            <material name="orange"/>
        </visual>
        <collision>
            <origin xyz="0 0 0.1525" rpy="0 0 0"/>
            <geometry>
                <mesh filename="file:///home/jirapat/models/base.dae" scale="1 1 1"/>
            </geometry>
        </collision>
        <xacro:inertial_box mass="0.5" x="1" y="1" z="0.2">
            <origin xyz="0 0 0.35" rpy="0 0 0"/>
        </xacro:inertial_box>
    </link>
    
    <gazebo reference="base">
        <material>Gazebo/Orange</material>
        <mu1>1</mu1>
        <mu2>1</mu2>
    </gazebo>
    
    <!--FrontWheel-->
    <joint name="WheelFront_joint" type="continuous">
        <parent link="original"/>
        <child link="WheelFront"/>
        <origin xyz="0.5 -0.65 0.175"/>
        <axis xyz="0 1 0"/>
    </joint>

    <link name="WheelFront">
        <visual>
            <origin xyz="0 0 -0.175" rpy="0 0 0"/>
            <geometry>
                <mesh filename="file:///home/jirapat/models/WheelFront.dae" scale="1 1 1"/>
            </geometry>
            <material name="blue"/>
        </visual>
        <collision>
            <origin xyz="0 0 -0.175" rpy="0 0 0"/>
            <geometry>
                <mesh filename="file:///home/jirapat/models/WheelFront.dae" scale="1 1 1"/>
            </geometry>
        </collision>
        <xacro:inertial_cylinder mass="0.1" length="0.1" radius="0.07">
            <origin xyz="0 0 0" rpy="0 0 0"/>
        </xacro:inertial_cylinder>
    </link>
    
    <gazebo reference="WheelFront">
        <material>Gazebo/Blue</material>
        <mu1>1</mu1>
        <mu2>1</mu2>
    </gazebo>

    <joint name="WheelFront1_joint" type="continuous">
        <parent link="original"/>
        <child link="WheelFront1"/>
        <origin xyz="-0.5 -0.65 0.175"/>
        <axis xyz="0 1 0"/>
    </joint>

    <link name="WheelFront1">
        <visual>
            <origin xyz="0 0 -0.175" rpy="0 0 0"/>
            <geometry>
                <mesh filename="file:///home/jirapat/models/WheelFront.dae" scale="1 1 1"/>
            </geometry>
            <material name="blue"/>
        </visual>
        <collision>
            <origin xyz="0 0 -0.175" rpy="0 0 0"/>
            <geometry>
                <mesh filename="file:///home/jirapat/models/WheelFront.dae" scale="1 1 1"/>
            </geometry>
        </collision>
        <xacro:inertial_cylinder mass="0.1" length="0.1" radius="0.07">
            <origin xyz="0 0 0" rpy="0 0 0"/>
        </xacro:inertial_cylinder>
    </link>
    
    <gazebo reference="WheelFront1">
        <material>Gazebo/Blue</material>
        <mu1>1</mu1>
        <mu2>1</mu2>
    </gazebo>

    <!--FrontBackWheel-->
    <joint name="WheelbackFront_joint" type="continuous">
        <parent link="original"/>
        <child link="WheelbackFront"/>
        <origin xyz="0.5 0.65 0.175"/>
        <axis xyz="0 1 0"/>
    </joint>

    <link name="WheelbackFront">
        <visual>
            <origin xyz="0 0 -0.175" rpy="0 0 0"/>
            <geometry>
                <mesh filename="file:///home/jirapat/models/WheelbackFront.dae" scale="1 1 1"/>
            </geometry>
            <material name="blue"/>
        </visual>
        <collision>
            <origin xyz="0 0 -0.175" rpy="0 0 0"/>
            <geometry>
                <mesh filename="file:///home/jirapat/models/WheelbackFront.dae" scale="1 1 1"/>
            </geometry>
        </collision>
        <xacro:inertial_cylinder mass="0.1" length="0.1" radius="0.07">
            <origin xyz="0 0 0" rpy="0 0 0"/>
        </xacro:inertial_cylinder>
    </link>
    
    <gazebo reference="WheelbackFront">
        <material>Gazebo/Blue</material>
        <mu1>1</mu1>
        <mu2>1</mu2>
    </gazebo>

    <joint name="WheelbackFront1_joint" type="continuous">
        <parent link="original"/>
        <child link="WheelbackFront1"/>
        <origin xyz="-0.5 0.65 0.175"/>
        <axis xyz="0 1 0"/>
    </joint>

    <link name="WheelbackFront1">
        <visual>
            <origin xyz="0 0 -0.175" rpy="0 0 0"/>
            <geometry>
                <mesh filename="file:///home/jirapat/models/WheelbackFront.dae" scale="1 1 1"/>
            </geometry>
            <material name="blue"/>
        </visual>
        <collision>
            <origin xyz="0 0 -0.175" rpy="0 0 0"/>
            <geometry>
                <mesh filename="file:///home/jirapat/models/WheelbackFront.dae" scale="1 1 1"/>
            </geometry>
        </collision>
        <xacro:inertial_cylinder mass="0.1" length="0.1" radius="0.07">
            <origin xyz="0 0 0" rpy="0 0 0"/>
        </xacro:inertial_cylinder>
    </link>
    
    <gazebo reference="WheelbackFront1">
        <material>Gazebo/Blue</material>
        <mu1>1</mu1>
        <mu2>1</mu2>
    </gazebo>

    <!--tow-->
    <joint name="tow_joint" type="fixed">
        <parent link="original"/>
        <child link="tow"/>
        <origin xyz="-0.85 0 0.30" rpy="0 0 ${pi/2}"/>
    </joint>

    <link name="tow">
        <visual>
            <origin xyz="0 0 0" rpy="0 0 0"/>
            <geometry>
                <mesh filename="file:///home/jirapat/models/tow.dae" scale="1 1 1"/>
            </geometry>
            <material name="red"/>
        </visual>
        <collision>
            <origin xyz="0 0 0" rpy="0 0 0"/>
            <geometry>
                <mesh filename="file:///home/jirapat/models/tow.dae" scale="1 1 1"/>
            </geometry>
        </collision>
        <xacro:inertial_box mass="0.01" x="0.5" y="0.5" z="0.05">
            <origin xyz="0 0 0" rpy="0 0 0"/>
        </xacro:inertial_box>
    </link>
    
    <gazebo reference="tow">
        <material>Gazebo/Red</material>
        <mu1>1</mu1>
        <mu2>1</mu2>
    </gazebo>
    
</robot>